<?xml version="1.0" encoding="UTF-8"?>
<testng-results skipped="0" failed="3" ignored="0" total="5" passed="2">
  <reporter-output>
  </reporter-output>
  <suite name="Suite" duration-ms="5473" started-at="2021-05-17T02:27:11Z" finished-at="2021-05-17T02:27:17Z">
    <groups>
    </groups>
    <test name="Create Customer API Test" duration-ms="3500" started-at="2021-05-17T02:27:11Z" finished-at="2021-05-17T02:27:15Z">
      <class name="com.w2a.APITestingFramework.testcases.CreateCustomerTest">
        <test-method status="FAIL" signature="validateCreateCustomerAPIWithInValidSecretKey(java.util.Hashtable)[pri:0, instance:com.w2a.APITestingFramework.testcases.CreateCustomerTest@662b4c69]" name="validateCreateCustomerAPIWithInValidSecretKey" duration-ms="2530" started-at="2021-05-17T02:27:11Z" data-provider="data" finished-at="2021-05-17T02:27:14Z">
          <params>
            <param index="0">
              <value>
                <![CDATA[{email=idiot1@gmail.com, name=idiot, description=this is me no1}]]>
              </value>
            </param>
          </params>
          <exception class="java.lang.AssertionError">
            <message>
              <![CDATA[expected [200] but found [401]]]>
            </message>
            <full-stacktrace>
              <![CDATA[java.lang.AssertionError: expected [200] but found [401]
at org.testng.Assert.fail(Assert.java:96)
at org.testng.Assert.failNotEquals(Assert.java:776)
at org.testng.Assert.assertEqualsImpl(Assert.java:137)
at org.testng.Assert.assertEquals(Assert.java:118)
at org.testng.Assert.assertEquals(Assert.java:652)
at org.testng.Assert.assertEquals(Assert.java:662)
at com.w2a.APITestingFramework.testcases.CreateCustomerTest.validateCreateCustomerAPIWithInValidSecretKey(CreateCustomerTest.java:41)
at sun.reflect.NativeMethodAccessorImpl.invoke0(Native Method)
at sun.reflect.NativeMethodAccessorImpl.invoke(NativeMethodAccessorImpl.java:62)
at sun.reflect.DelegatingMethodAccessorImpl.invoke(DelegatingMethodAccessorImpl.java:43)
at java.lang.reflect.Method.invoke(Method.java:498)
at org.testng.internal.MethodInvocationHelper.invokeMethod(MethodInvocationHelper.java:124)
at org.testng.internal.Invoker.invokeMethod(Invoker.java:583)
at org.testng.internal.Invoker.invokeTestMethod(Invoker.java:719)
at org.testng.internal.TestMethodWithDataProviderMethodWorker.call(TestMethodWithDataProviderMethodWorker.java:71)
at org.testng.internal.TestMethodWithDataProviderMethodWorker.call(TestMethodWithDataProviderMethodWorker.java:14)
at java.util.concurrent.FutureTask.run(FutureTask.java:266)
at java.util.concurrent.Executors$RunnableAdapter.call(Executors.java:511)
at java.util.concurrent.FutureTask.run(FutureTask.java:266)
at java.util.concurrent.ThreadPoolExecutor.runWorker(ThreadPoolExecutor.java:1149)
at java.util.concurrent.ThreadPoolExecutor$Worker.run(ThreadPoolExecutor.java:624)
at java.lang.Thread.run(Thread.java:748)
]]>
            </full-stacktrace>
          </exception> <!-- java.lang.AssertionError -->
          <reporter-output>
          </reporter-output>
        </test-method> <!-- validateCreateCustomerAPIWithInValidSecretKey -->
        <test-method status="PASS" signature="validateCreateCustomerAPIWithValidSecretKey(java.util.Hashtable)[pri:0, instance:com.w2a.APITestingFramework.testcases.CreateCustomerTest@662b4c69]" name="validateCreateCustomerAPIWithValidSecretKey" duration-ms="907" started-at="2021-05-17T02:27:14Z" data-provider="data" finished-at="2021-05-17T02:27:15Z">
          <params>
            <param index="0">
              <value>
                <![CDATA[{email=sam1@gmail.com, name=sam, description=this is me no1, address[postal_code]=123.0}]]>
              </value>
            </param>
          </params>
          <reporter-output>
          </reporter-output>
        </test-method> <!-- validateCreateCustomerAPIWithValidSecretKey -->
        <test-method status="PASS" signature="validateCreateCustomerAPIWithValidSecretKey(java.util.Hashtable)[pri:0, instance:com.w2a.APITestingFramework.testcases.CreateCustomerTest@662b4c69]" name="validateCreateCustomerAPIWithValidSecretKey" duration-ms="815" started-at="2021-05-17T02:27:14Z" data-provider="data" finished-at="2021-05-17T02:27:14Z">
          <params>
            <param index="0">
              <value>
                <![CDATA[{email=sam2@gmail.com, name=samuel, description=this is me no2, address[postal_code]=456.0}]]>
              </value>
            </param>
          </params>
          <reporter-output>
          </reporter-output>
        </test-method> <!-- validateCreateCustomerAPIWithValidSecretKey -->
      </class> <!-- com.w2a.APITestingFramework.testcases.CreateCustomerTest -->
    </test> <!-- Create Customer API Test -->
    <test name="Delete Customer API Test" duration-ms="1562" started-at="2021-05-17T02:27:15Z" finished-at="2021-05-17T02:27:17Z">
      <class name="com.w2a.APITestingFramework.testcases.DeleteCustomerTest2">
        <test-method status="PASS" signature="setUp()[pri:0, instance:com.w2a.APITestingFramework.testcases.DeleteCustomerTest2@22ef9844]" name="setUp" is-config="true" duration-ms="453" started-at="2021-05-17T02:27:11Z" finished-at="2021-05-17T02:27:11Z">
          <reporter-output>
          </reporter-output>
        </test-method> <!-- setUp -->
        <test-method status="FAIL" signature="validateDeleteCustomerAPI(java.util.Hashtable)[pri:0, instance:com.w2a.APITestingFramework.testcases.DeleteCustomerTest2@22ef9844]" name="validateDeleteCustomerAPI" duration-ms="1555" started-at="2021-05-17T02:27:15Z" data-provider="data" finished-at="2021-05-17T02:27:16Z">
          <params>
            <param index="0">
              <value>
                <![CDATA[{id=cus_JUcwzQCosxT91x}]]>
              </value>
            </param>
          </params>
          <exception class="java.lang.AssertionError">
            <message>
              <![CDATA[expected [200] but found [404]]]>
            </message>
            <full-stacktrace>
              <![CDATA[java.lang.AssertionError: expected [200] but found [404]
at org.testng.Assert.fail(Assert.java:96)
at org.testng.Assert.failNotEquals(Assert.java:776)
at org.testng.Assert.assertEqualsImpl(Assert.java:137)
at org.testng.Assert.assertEquals(Assert.java:118)
at org.testng.Assert.assertEquals(Assert.java:652)
at org.testng.Assert.assertEquals(Assert.java:662)
at com.w2a.APITestingFramework.testcases.DeleteCustomerTest2.validateDeleteCustomerAPI(DeleteCustomerTest2.java:35)
at sun.reflect.NativeMethodAccessorImpl.invoke0(Native Method)
at sun.reflect.NativeMethodAccessorImpl.invoke(NativeMethodAccessorImpl.java:62)
at sun.reflect.DelegatingMethodAccessorImpl.invoke(DelegatingMethodAccessorImpl.java:43)
at java.lang.reflect.Method.invoke(Method.java:498)
at org.testng.internal.MethodInvocationHelper.invokeMethod(MethodInvocationHelper.java:124)
at org.testng.internal.Invoker.invokeMethod(Invoker.java:583)
at org.testng.internal.Invoker.invokeTestMethod(Invoker.java:719)
at org.testng.internal.TestMethodWithDataProviderMethodWorker.call(TestMethodWithDataProviderMethodWorker.java:71)
at org.testng.internal.TestMethodWithDataProviderMethodWorker.call(TestMethodWithDataProviderMethodWorker.java:14)
at java.util.concurrent.FutureTask.run(FutureTask.java:266)
at java.util.concurrent.Executors$RunnableAdapter.call(Executors.java:511)
at java.util.concurrent.FutureTask.run(FutureTask.java:266)
at java.util.concurrent.ThreadPoolExecutor.runWorker(ThreadPoolExecutor.java:1149)
at java.util.concurrent.ThreadPoolExecutor$Worker.run(ThreadPoolExecutor.java:624)
at java.lang.Thread.run(Thread.java:748)
]]>
            </full-stacktrace>
          </exception> <!-- java.lang.AssertionError -->
          <reporter-output>
          </reporter-output>
        </test-method> <!-- validateDeleteCustomerAPI -->
        <test-method status="FAIL" signature="validateDeleteCustomerAPI(java.util.Hashtable)[pri:0, instance:com.w2a.APITestingFramework.testcases.DeleteCustomerTest2@22ef9844]" name="validateDeleteCustomerAPI" duration-ms="795" started-at="2021-05-17T02:27:15Z" data-provider="data" finished-at="2021-05-17T02:27:16Z">
          <params>
            <param index="0">
              <value>
                <![CDATA[{id=cus_Ih4nqWuWxyGD95}]]>
              </value>
            </param>
          </params>
          <exception class="java.lang.AssertionError">
            <message>
              <![CDATA[expected [200] but found [404]]]>
            </message>
            <full-stacktrace>
              <![CDATA[java.lang.AssertionError: expected [200] but found [404]
at org.testng.Assert.fail(Assert.java:96)
at org.testng.Assert.failNotEquals(Assert.java:776)
at org.testng.Assert.assertEqualsImpl(Assert.java:137)
at org.testng.Assert.assertEquals(Assert.java:118)
at org.testng.Assert.assertEquals(Assert.java:652)
at org.testng.Assert.assertEquals(Assert.java:662)
at com.w2a.APITestingFramework.testcases.DeleteCustomerTest2.validateDeleteCustomerAPI(DeleteCustomerTest2.java:35)
at sun.reflect.NativeMethodAccessorImpl.invoke0(Native Method)
at sun.reflect.NativeMethodAccessorImpl.invoke(NativeMethodAccessorImpl.java:62)
at sun.reflect.DelegatingMethodAccessorImpl.invoke(DelegatingMethodAccessorImpl.java:43)
at java.lang.reflect.Method.invoke(Method.java:498)
at org.testng.internal.MethodInvocationHelper.invokeMethod(MethodInvocationHelper.java:124)
at org.testng.internal.Invoker.invokeMethod(Invoker.java:583)
at org.testng.internal.Invoker.invokeTestMethod(Invoker.java:719)
at org.testng.internal.TestMethodWithDataProviderMethodWorker.call(TestMethodWithDataProviderMethodWorker.java:71)
at org.testng.internal.TestMethodWithDataProviderMethodWorker.call(TestMethodWithDataProviderMethodWorker.java:14)
at java.util.concurrent.FutureTask.run(FutureTask.java:266)
at java.util.concurrent.Executors$RunnableAdapter.call(Executors.java:511)
at java.util.concurrent.FutureTask.run(FutureTask.java:266)
at java.util.concurrent.ThreadPoolExecutor.runWorker(ThreadPoolExecutor.java:1149)
at java.util.concurrent.ThreadPoolExecutor$Worker.run(ThreadPoolExecutor.java:624)
at java.lang.Thread.run(Thread.java:748)
]]>
            </full-stacktrace>
          </exception> <!-- java.lang.AssertionError -->
          <reporter-output>
          </reporter-output>
        </test-method> <!-- validateDeleteCustomerAPI -->
        <test-method status="PASS" signature="tearDown()[pri:0, instance:com.w2a.APITestingFramework.testcases.DeleteCustomerTest2@22ef9844]" name="tearDown" is-config="true" duration-ms="0" started-at="2021-05-17T02:27:17Z" finished-at="2021-05-17T02:27:17Z">
          <reporter-output>
          </reporter-output>
        </test-method> <!-- tearDown -->
      </class> <!-- com.w2a.APITestingFramework.testcases.DeleteCustomerTest2 -->
    </test> <!-- Delete Customer API Test -->
  </suite> <!-- Suite -->
</testng-results>
