<?xml version="1.0" encoding="UTF-8"?>
<testng-results ignored="0" total="5" passed="2" failed="3" skipped="0">
  <reporter-output>
  </reporter-output>
  <suite started-at="2021-05-16T23:11:28Z" name="Suite" finished-at="2021-05-16T23:11:33Z" duration-ms="4406">
    <groups>
    </groups>
    <test started-at="2021-05-16T23:11:28Z" name="Create Customer API Test" finished-at="2021-05-16T23:11:31Z" duration-ms="2986">
      <class name="com.w2a.APITestingFramework.testcases.CreateCustomerTest">
        <test-method signature="validateCreateCustomerAPIWithInValidSecretKey(java.util.Hashtable)[pri:0, instance:com.w2a.APITestingFramework.testcases.CreateCustomerTest@64b73e7a]" started-at="2021-05-16T23:11:28Z" name="validateCreateCustomerAPIWithInValidSecretKey" data-provider="data" finished-at="2021-05-16T23:11:30Z" duration-ms="2012" status="FAIL">
          <params>
            <param index="0">
              <value>
                <![CDATA[{email=idiot1@gmail.com, name=idiot, description=this is me no1}]]>
              </value>
            </param>
          </params>
          <exception class="java.lang.AssertionError">
            <message>
              <![CDATA[expected [200] but found [401]]]>
            </message>
            <full-stacktrace>
              <![CDATA[java.lang.AssertionError: expected [200] but found [401]
at org.testng.Assert.fail(Assert.java:96)
at org.testng.Assert.failNotEquals(Assert.java:776)
at org.testng.Assert.assertEqualsImpl(Assert.java:137)
at org.testng.Assert.assertEquals(Assert.java:118)
at org.testng.Assert.assertEquals(Assert.java:652)
at org.testng.Assert.assertEquals(Assert.java:662)
at com.w2a.APITestingFramework.testcases.CreateCustomerTest.validateCreateCustomerAPIWithInValidSecretKey(CreateCustomerTest.java:41)
at java.base/jdk.internal.reflect.NativeMethodAccessorImpl.invoke0(Native Method)
at java.base/jdk.internal.reflect.NativeMethodAccessorImpl.invoke(NativeMethodAccessorImpl.java:62)
at java.base/jdk.internal.reflect.DelegatingMethodAccessorImpl.invoke(DelegatingMethodAccessorImpl.java:43)
at java.base/java.lang.reflect.Method.invoke(Method.java:564)
at org.testng.internal.MethodInvocationHelper.invokeMethod(MethodInvocationHelper.java:124)
at org.testng.internal.Invoker.invokeMethod(Invoker.java:583)
at org.testng.internal.Invoker.invokeTestMethod(Invoker.java:719)
at org.testng.internal.TestMethodWithDataProviderMethodWorker.call(TestMethodWithDataProviderMethodWorker.java:71)
at org.testng.internal.TestMethodWithDataProviderMethodWorker.call(TestMethodWithDataProviderMethodWorker.java:14)
at java.base/java.util.concurrent.FutureTask.run(FutureTask.java:264)
at java.base/java.util.concurrent.Executors$RunnableAdapter.call(Executors.java:515)
at java.base/java.util.concurrent.FutureTask.run(FutureTask.java:264)
at java.base/java.util.concurrent.ThreadPoolExecutor.runWorker(ThreadPoolExecutor.java:1130)
at java.base/java.util.concurrent.ThreadPoolExecutor$Worker.run(ThreadPoolExecutor.java:630)
at java.base/java.lang.Thread.run(Thread.java:832)
]]>
            </full-stacktrace>
          </exception> <!-- java.lang.AssertionError -->
          <reporter-output>
          </reporter-output>
        </test-method> <!-- validateCreateCustomerAPIWithInValidSecretKey -->
        <test-method signature="validateCreateCustomerAPIWithValidSecretKey(java.util.Hashtable)[pri:0, instance:com.w2a.APITestingFramework.testcases.CreateCustomerTest@64b73e7a]" started-at="2021-05-16T23:11:30Z" name="validateCreateCustomerAPIWithValidSecretKey" data-provider="data" finished-at="2021-05-16T23:11:31Z" duration-ms="914" status="PASS">
          <params>
            <param index="0">
              <value>
                <![CDATA[{email=sam2@gmail.com, name=samuel, description=this is me no2, address[postal_code]=456.0}]]>
              </value>
            </param>
          </params>
          <reporter-output>
          </reporter-output>
        </test-method> <!-- validateCreateCustomerAPIWithValidSecretKey -->
        <test-method signature="validateCreateCustomerAPIWithValidSecretKey(java.util.Hashtable)[pri:0, instance:com.w2a.APITestingFramework.testcases.CreateCustomerTest@64b73e7a]" started-at="2021-05-16T23:11:30Z" name="validateCreateCustomerAPIWithValidSecretKey" data-provider="data" finished-at="2021-05-16T23:11:31Z" duration-ms="799" status="PASS">
          <params>
            <param index="0">
              <value>
                <![CDATA[{email=sam1@gmail.com, name=sam, description=this is me no1, address[postal_code]=123.0}]]>
              </value>
            </param>
          </params>
          <reporter-output>
          </reporter-output>
        </test-method> <!-- validateCreateCustomerAPIWithValidSecretKey -->
      </class> <!-- com.w2a.APITestingFramework.testcases.CreateCustomerTest -->
    </test> <!-- Create Customer API Test -->
    <test started-at="2021-05-16T23:11:32Z" name="Delete Customer API Test" finished-at="2021-05-16T23:11:33Z" duration-ms="903">
      <class name="com.w2a.APITestingFramework.testcases.DeleteCustomerTest2">
        <test-method is-config="true" signature="setUp()[pri:0, instance:com.w2a.APITestingFramework.testcases.DeleteCustomerTest2@79d94571]" started-at="2021-05-16T23:11:28Z" name="setUp" finished-at="2021-05-16T23:11:28Z" duration-ms="587" status="PASS">
          <reporter-output>
          </reporter-output>
        </test-method> <!-- setUp -->
        <test-method signature="validateDeleteCustomerAPI(java.util.Hashtable)[pri:0, instance:com.w2a.APITestingFramework.testcases.DeleteCustomerTest2@79d94571]" started-at="2021-05-16T23:11:32Z" name="validateDeleteCustomerAPI" data-provider="data" finished-at="2021-05-16T23:11:32Z" duration-ms="780" status="FAIL">
          <params>
            <param index="0">
              <value>
                <![CDATA[{id=cus_Ih4nqWuWxyGD95}]]>
              </value>
            </param>
          </params>
          <exception class="java.lang.AssertionError">
            <message>
              <![CDATA[expected [200] but found [404]]]>
            </message>
            <full-stacktrace>
              <![CDATA[java.lang.AssertionError: expected [200] but found [404]
at org.testng.Assert.fail(Assert.java:96)
at org.testng.Assert.failNotEquals(Assert.java:776)
at org.testng.Assert.assertEqualsImpl(Assert.java:137)
at org.testng.Assert.assertEquals(Assert.java:118)
at org.testng.Assert.assertEquals(Assert.java:652)
at org.testng.Assert.assertEquals(Assert.java:662)
at com.w2a.APITestingFramework.testcases.DeleteCustomerTest2.validateDeleteCustomerAPI(DeleteCustomerTest2.java:35)
at java.base/jdk.internal.reflect.NativeMethodAccessorImpl.invoke0(Native Method)
at java.base/jdk.internal.reflect.NativeMethodAccessorImpl.invoke(NativeMethodAccessorImpl.java:62)
at java.base/jdk.internal.reflect.DelegatingMethodAccessorImpl.invoke(DelegatingMethodAccessorImpl.java:43)
at java.base/java.lang.reflect.Method.invoke(Method.java:564)
at org.testng.internal.MethodInvocationHelper.invokeMethod(MethodInvocationHelper.java:124)
at org.testng.internal.Invoker.invokeMethod(Invoker.java:583)
at org.testng.internal.Invoker.invokeTestMethod(Invoker.java:719)
at org.testng.internal.TestMethodWithDataProviderMethodWorker.call(TestMethodWithDataProviderMethodWorker.java:71)
at org.testng.internal.TestMethodWithDataProviderMethodWorker.call(TestMethodWithDataProviderMethodWorker.java:14)
at java.base/java.util.concurrent.FutureTask.run(FutureTask.java:264)
at java.base/java.util.concurrent.Executors$RunnableAdapter.call(Executors.java:515)
at java.base/java.util.concurrent.FutureTask.run(FutureTask.java:264)
at java.base/java.util.concurrent.ThreadPoolExecutor.runWorker(ThreadPoolExecutor.java:1130)
at java.base/java.util.concurrent.ThreadPoolExecutor$Worker.run(ThreadPoolExecutor.java:630)
at java.base/java.lang.Thread.run(Thread.java:832)
]]>
            </full-stacktrace>
          </exception> <!-- java.lang.AssertionError -->
          <reporter-output>
          </reporter-output>
        </test-method> <!-- validateDeleteCustomerAPI -->
        <test-method signature="validateDeleteCustomerAPI(java.util.Hashtable)[pri:0, instance:com.w2a.APITestingFramework.testcases.DeleteCustomerTest2@79d94571]" started-at="2021-05-16T23:11:32Z" name="validateDeleteCustomerAPI" data-provider="data" finished-at="2021-05-16T23:11:33Z" duration-ms="893" status="FAIL">
          <params>
            <param index="0">
              <value>
                <![CDATA[{id=cus_JUcwzQCosxT91x}]]>
              </value>
            </param>
          </params>
          <exception class="java.lang.AssertionError">
            <message>
              <![CDATA[expected [200] but found [404]]]>
            </message>
            <full-stacktrace>
              <![CDATA[java.lang.AssertionError: expected [200] but found [404]
at org.testng.Assert.fail(Assert.java:96)
at org.testng.Assert.failNotEquals(Assert.java:776)
at org.testng.Assert.assertEqualsImpl(Assert.java:137)
at org.testng.Assert.assertEquals(Assert.java:118)
at org.testng.Assert.assertEquals(Assert.java:652)
at org.testng.Assert.assertEquals(Assert.java:662)
at com.w2a.APITestingFramework.testcases.DeleteCustomerTest2.validateDeleteCustomerAPI(DeleteCustomerTest2.java:35)
at java.base/jdk.internal.reflect.NativeMethodAccessorImpl.invoke0(Native Method)
at java.base/jdk.internal.reflect.NativeMethodAccessorImpl.invoke(NativeMethodAccessorImpl.java:62)
at java.base/jdk.internal.reflect.DelegatingMethodAccessorImpl.invoke(DelegatingMethodAccessorImpl.java:43)
at java.base/java.lang.reflect.Method.invoke(Method.java:564)
at org.testng.internal.MethodInvocationHelper.invokeMethod(MethodInvocationHelper.java:124)
at org.testng.internal.Invoker.invokeMethod(Invoker.java:583)
at org.testng.internal.Invoker.invokeTestMethod(Invoker.java:719)
at org.testng.internal.TestMethodWithDataProviderMethodWorker.call(TestMethodWithDataProviderMethodWorker.java:71)
at org.testng.internal.TestMethodWithDataProviderMethodWorker.call(TestMethodWithDataProviderMethodWorker.java:14)
at java.base/java.util.concurrent.FutureTask.run(FutureTask.java:264)
at java.base/java.util.concurrent.Executors$RunnableAdapter.call(Executors.java:515)
at java.base/java.util.concurrent.FutureTask.run(FutureTask.java:264)
at java.base/java.util.concurrent.ThreadPoolExecutor.runWorker(ThreadPoolExecutor.java:1130)
at java.base/java.util.concurrent.ThreadPoolExecutor$Worker.run(ThreadPoolExecutor.java:630)
at java.base/java.lang.Thread.run(Thread.java:832)
]]>
            </full-stacktrace>
          </exception> <!-- java.lang.AssertionError -->
          <reporter-output>
          </reporter-output>
        </test-method> <!-- validateDeleteCustomerAPI -->
        <test-method is-config="true" signature="tearDown()[pri:0, instance:com.w2a.APITestingFramework.testcases.DeleteCustomerTest2@79d94571]" started-at="2021-05-16T23:11:33Z" name="tearDown" finished-at="2021-05-16T23:11:33Z" duration-ms="1" status="PASS">
          <reporter-output>
          </reporter-output>
        </test-method> <!-- tearDown -->
      </class> <!-- com.w2a.APITestingFramework.testcases.DeleteCustomerTest2 -->
    </test> <!-- Delete Customer API Test -->
  </suite> <!-- Suite -->
</testng-results>
